{
 "cells": [
  {
   "cell_type": "code",
   "execution_count": 2,
   "id": "dbd57a38",
   "metadata": {},
   "outputs": [
    {
     "name": "stdout",
     "output_type": "stream",
     "text": [
      "WARNING:tensorflow:From C:\\Users\\91779\\anaconda3\\lib\\site-packages\\keras\\src\\backend.py:873: The name tf.get_default_graph is deprecated. Please use tf.compat.v1.get_default_graph instead.\n",
      "\n",
      "WARNING:tensorflow:From C:\\Users\\91779\\anaconda3\\lib\\site-packages\\keras\\src\\optimizers\\__init__.py:309: The name tf.train.Optimizer is deprecated. Please use tf.compat.v1.train.Optimizer instead.\n",
      "\n",
      "Epoch 1/10\n",
      "WARNING:tensorflow:From C:\\Users\\91779\\anaconda3\\lib\\site-packages\\keras\\src\\utils\\tf_utils.py:492: The name tf.ragged.RaggedTensorValue is deprecated. Please use tf.compat.v1.ragged.RaggedTensorValue instead.\n",
      "\n",
      "WARNING:tensorflow:From C:\\Users\\91779\\anaconda3\\lib\\site-packages\\keras\\src\\engine\\base_layer_utils.py:384: The name tf.executing_eagerly_outside_functions is deprecated. Please use tf.compat.v1.executing_eagerly_outside_functions instead.\n",
      "\n"
     ]
    },
    {
     "ename": "UnimplementedError",
     "evalue": "Graph execution error:\n\nDetected at node binary_crossentropy/Cast defined at (most recent call last):\n  File \"C:\\Users\\91779\\anaconda3\\lib\\runpy.py\", line 196, in _run_module_as_main\n\n  File \"C:\\Users\\91779\\anaconda3\\lib\\runpy.py\", line 86, in _run_code\n\n  File \"C:\\Users\\91779\\anaconda3\\lib\\site-packages\\ipykernel_launcher.py\", line 17, in <module>\n\n  File \"C:\\Users\\91779\\anaconda3\\lib\\site-packages\\traitlets\\config\\application.py\", line 992, in launch_instance\n\n  File \"C:\\Users\\91779\\anaconda3\\lib\\site-packages\\ipykernel\\kernelapp.py\", line 711, in start\n\n  File \"C:\\Users\\91779\\anaconda3\\lib\\site-packages\\tornado\\platform\\asyncio.py\", line 199, in start\n\n  File \"C:\\Users\\91779\\anaconda3\\lib\\asyncio\\base_events.py\", line 603, in run_forever\n\n  File \"C:\\Users\\91779\\anaconda3\\lib\\asyncio\\base_events.py\", line 1906, in _run_once\n\n  File \"C:\\Users\\91779\\anaconda3\\lib\\asyncio\\events.py\", line 80, in _run\n\n  File \"C:\\Users\\91779\\anaconda3\\lib\\site-packages\\ipykernel\\kernelbase.py\", line 510, in dispatch_queue\n\n  File \"C:\\Users\\91779\\anaconda3\\lib\\site-packages\\ipykernel\\kernelbase.py\", line 499, in process_one\n\n  File \"C:\\Users\\91779\\anaconda3\\lib\\site-packages\\ipykernel\\kernelbase.py\", line 406, in dispatch_shell\n\n  File \"C:\\Users\\91779\\anaconda3\\lib\\site-packages\\ipykernel\\kernelbase.py\", line 729, in execute_request\n\n  File \"C:\\Users\\91779\\anaconda3\\lib\\site-packages\\ipykernel\\ipkernel.py\", line 411, in do_execute\n\n  File \"C:\\Users\\91779\\anaconda3\\lib\\site-packages\\ipykernel\\zmqshell.py\", line 531, in run_cell\n\n  File \"C:\\Users\\91779\\anaconda3\\lib\\site-packages\\IPython\\core\\interactiveshell.py\", line 2961, in run_cell\n\n  File \"C:\\Users\\91779\\anaconda3\\lib\\site-packages\\IPython\\core\\interactiveshell.py\", line 3016, in _run_cell\n\n  File \"C:\\Users\\91779\\anaconda3\\lib\\site-packages\\IPython\\core\\async_helpers.py\", line 129, in _pseudo_sync_runner\n\n  File \"C:\\Users\\91779\\anaconda3\\lib\\site-packages\\IPython\\core\\interactiveshell.py\", line 3221, in run_cell_async\n\n  File \"C:\\Users\\91779\\anaconda3\\lib\\site-packages\\IPython\\core\\interactiveshell.py\", line 3400, in run_ast_nodes\n\n  File \"C:\\Users\\91779\\anaconda3\\lib\\site-packages\\IPython\\core\\interactiveshell.py\", line 3460, in run_code\n\n  File \"C:\\Users\\91779\\AppData\\Local\\Temp\\ipykernel_18204\\1126896864.py\", line 46, in <module>\n\n  File \"C:\\Users\\91779\\anaconda3\\lib\\site-packages\\keras\\src\\utils\\traceback_utils.py\", line 65, in error_handler\n\n  File \"C:\\Users\\91779\\anaconda3\\lib\\site-packages\\keras\\src\\engine\\training.py\", line 1807, in fit\n\n  File \"C:\\Users\\91779\\anaconda3\\lib\\site-packages\\keras\\src\\engine\\training.py\", line 1401, in train_function\n\n  File \"C:\\Users\\91779\\anaconda3\\lib\\site-packages\\keras\\src\\engine\\training.py\", line 1384, in step_function\n\n  File \"C:\\Users\\91779\\anaconda3\\lib\\site-packages\\keras\\src\\engine\\training.py\", line 1373, in run_step\n\n  File \"C:\\Users\\91779\\anaconda3\\lib\\site-packages\\keras\\src\\engine\\training.py\", line 1151, in train_step\n\n  File \"C:\\Users\\91779\\anaconda3\\lib\\site-packages\\keras\\src\\engine\\training.py\", line 1209, in compute_loss\n\n  File \"C:\\Users\\91779\\anaconda3\\lib\\site-packages\\keras\\src\\engine\\compile_utils.py\", line 277, in __call__\n\n  File \"C:\\Users\\91779\\anaconda3\\lib\\site-packages\\keras\\src\\losses.py\", line 143, in __call__\n\n  File \"C:\\Users\\91779\\anaconda3\\lib\\site-packages\\keras\\src\\losses.py\", line 270, in call\n\n  File \"C:\\Users\\91779\\anaconda3\\lib\\site-packages\\keras\\src\\losses.py\", line 2521, in binary_crossentropy\n\nCast string to float is not supported\n\t [[{{node binary_crossentropy/Cast}}]] [Op:__inference_train_function_1081]",
     "output_type": "error",
     "traceback": [
      "\u001b[1;31m---------------------------------------------------------------------------\u001b[0m",
      "\u001b[1;31mUnimplementedError\u001b[0m                        Traceback (most recent call last)",
      "Cell \u001b[1;32mIn[2], line 46\u001b[0m\n\u001b[0;32m     43\u001b[0m model\u001b[38;5;241m.\u001b[39mcompile(optimizer\u001b[38;5;241m=\u001b[39m\u001b[38;5;124m'\u001b[39m\u001b[38;5;124madam\u001b[39m\u001b[38;5;124m'\u001b[39m, loss\u001b[38;5;241m=\u001b[39m\u001b[38;5;124m'\u001b[39m\u001b[38;5;124mbinary_crossentropy\u001b[39m\u001b[38;5;124m'\u001b[39m, metrics\u001b[38;5;241m=\u001b[39m[\u001b[38;5;124m'\u001b[39m\u001b[38;5;124maccuracy\u001b[39m\u001b[38;5;124m'\u001b[39m])\n\u001b[0;32m     45\u001b[0m \u001b[38;5;66;03m# Train the model\u001b[39;00m\n\u001b[1;32m---> 46\u001b[0m history \u001b[38;5;241m=\u001b[39m \u001b[43mmodel\u001b[49m\u001b[38;5;241;43m.\u001b[39;49m\u001b[43mfit\u001b[49m\u001b[43m(\u001b[49m\u001b[43mX_train\u001b[49m\u001b[43m,\u001b[49m\u001b[43m \u001b[49m\u001b[43my_train\u001b[49m\u001b[43m,\u001b[49m\u001b[43m \u001b[49m\u001b[43mepochs\u001b[49m\u001b[38;5;241;43m=\u001b[39;49m\u001b[38;5;241;43m10\u001b[39;49m\u001b[43m,\u001b[49m\u001b[43m \u001b[49m\u001b[43mbatch_size\u001b[49m\u001b[38;5;241;43m=\u001b[39;49m\u001b[38;5;241;43m32\u001b[39;49m\u001b[43m,\u001b[49m\u001b[43m \u001b[49m\u001b[43mvalidation_data\u001b[49m\u001b[38;5;241;43m=\u001b[39;49m\u001b[43m(\u001b[49m\u001b[43mX_val\u001b[49m\u001b[43m,\u001b[49m\u001b[43m \u001b[49m\u001b[43my_val\u001b[49m\u001b[43m)\u001b[49m\u001b[43m)\u001b[49m\n\u001b[0;32m     48\u001b[0m \u001b[38;5;66;03m# Evaluate the model on the test set\u001b[39;00m\n\u001b[0;32m     49\u001b[0m test_loss, test_acc \u001b[38;5;241m=\u001b[39m model\u001b[38;5;241m.\u001b[39mevaluate(X_test, y_test)\n",
      "File \u001b[1;32m~\\anaconda3\\lib\\site-packages\\keras\\src\\utils\\traceback_utils.py:70\u001b[0m, in \u001b[0;36mfilter_traceback.<locals>.error_handler\u001b[1;34m(*args, **kwargs)\u001b[0m\n\u001b[0;32m     67\u001b[0m     filtered_tb \u001b[38;5;241m=\u001b[39m _process_traceback_frames(e\u001b[38;5;241m.\u001b[39m__traceback__)\n\u001b[0;32m     68\u001b[0m     \u001b[38;5;66;03m# To get the full stack trace, call:\u001b[39;00m\n\u001b[0;32m     69\u001b[0m     \u001b[38;5;66;03m# `tf.debugging.disable_traceback_filtering()`\u001b[39;00m\n\u001b[1;32m---> 70\u001b[0m     \u001b[38;5;28;01mraise\u001b[39;00m e\u001b[38;5;241m.\u001b[39mwith_traceback(filtered_tb) \u001b[38;5;28;01mfrom\u001b[39;00m \u001b[38;5;28mNone\u001b[39m\n\u001b[0;32m     71\u001b[0m \u001b[38;5;28;01mfinally\u001b[39;00m:\n\u001b[0;32m     72\u001b[0m     \u001b[38;5;28;01mdel\u001b[39;00m filtered_tb\n",
      "File \u001b[1;32m~\\anaconda3\\lib\\site-packages\\tensorflow\\python\\eager\\execute.py:53\u001b[0m, in \u001b[0;36mquick_execute\u001b[1;34m(op_name, num_outputs, inputs, attrs, ctx, name)\u001b[0m\n\u001b[0;32m     51\u001b[0m \u001b[38;5;28;01mtry\u001b[39;00m:\n\u001b[0;32m     52\u001b[0m   ctx\u001b[38;5;241m.\u001b[39mensure_initialized()\n\u001b[1;32m---> 53\u001b[0m   tensors \u001b[38;5;241m=\u001b[39m pywrap_tfe\u001b[38;5;241m.\u001b[39mTFE_Py_Execute(ctx\u001b[38;5;241m.\u001b[39m_handle, device_name, op_name,\n\u001b[0;32m     54\u001b[0m                                       inputs, attrs, num_outputs)\n\u001b[0;32m     55\u001b[0m \u001b[38;5;28;01mexcept\u001b[39;00m core\u001b[38;5;241m.\u001b[39m_NotOkStatusException \u001b[38;5;28;01mas\u001b[39;00m e:\n\u001b[0;32m     56\u001b[0m   \u001b[38;5;28;01mif\u001b[39;00m name \u001b[38;5;129;01mis\u001b[39;00m \u001b[38;5;129;01mnot\u001b[39;00m \u001b[38;5;28;01mNone\u001b[39;00m:\n",
      "\u001b[1;31mUnimplementedError\u001b[0m: Graph execution error:\n\nDetected at node binary_crossentropy/Cast defined at (most recent call last):\n  File \"C:\\Users\\91779\\anaconda3\\lib\\runpy.py\", line 196, in _run_module_as_main\n\n  File \"C:\\Users\\91779\\anaconda3\\lib\\runpy.py\", line 86, in _run_code\n\n  File \"C:\\Users\\91779\\anaconda3\\lib\\site-packages\\ipykernel_launcher.py\", line 17, in <module>\n\n  File \"C:\\Users\\91779\\anaconda3\\lib\\site-packages\\traitlets\\config\\application.py\", line 992, in launch_instance\n\n  File \"C:\\Users\\91779\\anaconda3\\lib\\site-packages\\ipykernel\\kernelapp.py\", line 711, in start\n\n  File \"C:\\Users\\91779\\anaconda3\\lib\\site-packages\\tornado\\platform\\asyncio.py\", line 199, in start\n\n  File \"C:\\Users\\91779\\anaconda3\\lib\\asyncio\\base_events.py\", line 603, in run_forever\n\n  File \"C:\\Users\\91779\\anaconda3\\lib\\asyncio\\base_events.py\", line 1906, in _run_once\n\n  File \"C:\\Users\\91779\\anaconda3\\lib\\asyncio\\events.py\", line 80, in _run\n\n  File \"C:\\Users\\91779\\anaconda3\\lib\\site-packages\\ipykernel\\kernelbase.py\", line 510, in dispatch_queue\n\n  File \"C:\\Users\\91779\\anaconda3\\lib\\site-packages\\ipykernel\\kernelbase.py\", line 499, in process_one\n\n  File \"C:\\Users\\91779\\anaconda3\\lib\\site-packages\\ipykernel\\kernelbase.py\", line 406, in dispatch_shell\n\n  File \"C:\\Users\\91779\\anaconda3\\lib\\site-packages\\ipykernel\\kernelbase.py\", line 729, in execute_request\n\n  File \"C:\\Users\\91779\\anaconda3\\lib\\site-packages\\ipykernel\\ipkernel.py\", line 411, in do_execute\n\n  File \"C:\\Users\\91779\\anaconda3\\lib\\site-packages\\ipykernel\\zmqshell.py\", line 531, in run_cell\n\n  File \"C:\\Users\\91779\\anaconda3\\lib\\site-packages\\IPython\\core\\interactiveshell.py\", line 2961, in run_cell\n\n  File \"C:\\Users\\91779\\anaconda3\\lib\\site-packages\\IPython\\core\\interactiveshell.py\", line 3016, in _run_cell\n\n  File \"C:\\Users\\91779\\anaconda3\\lib\\site-packages\\IPython\\core\\async_helpers.py\", line 129, in _pseudo_sync_runner\n\n  File \"C:\\Users\\91779\\anaconda3\\lib\\site-packages\\IPython\\core\\interactiveshell.py\", line 3221, in run_cell_async\n\n  File \"C:\\Users\\91779\\anaconda3\\lib\\site-packages\\IPython\\core\\interactiveshell.py\", line 3400, in run_ast_nodes\n\n  File \"C:\\Users\\91779\\anaconda3\\lib\\site-packages\\IPython\\core\\interactiveshell.py\", line 3460, in run_code\n\n  File \"C:\\Users\\91779\\AppData\\Local\\Temp\\ipykernel_18204\\1126896864.py\", line 46, in <module>\n\n  File \"C:\\Users\\91779\\anaconda3\\lib\\site-packages\\keras\\src\\utils\\traceback_utils.py\", line 65, in error_handler\n\n  File \"C:\\Users\\91779\\anaconda3\\lib\\site-packages\\keras\\src\\engine\\training.py\", line 1807, in fit\n\n  File \"C:\\Users\\91779\\anaconda3\\lib\\site-packages\\keras\\src\\engine\\training.py\", line 1401, in train_function\n\n  File \"C:\\Users\\91779\\anaconda3\\lib\\site-packages\\keras\\src\\engine\\training.py\", line 1384, in step_function\n\n  File \"C:\\Users\\91779\\anaconda3\\lib\\site-packages\\keras\\src\\engine\\training.py\", line 1373, in run_step\n\n  File \"C:\\Users\\91779\\anaconda3\\lib\\site-packages\\keras\\src\\engine\\training.py\", line 1151, in train_step\n\n  File \"C:\\Users\\91779\\anaconda3\\lib\\site-packages\\keras\\src\\engine\\training.py\", line 1209, in compute_loss\n\n  File \"C:\\Users\\91779\\anaconda3\\lib\\site-packages\\keras\\src\\engine\\compile_utils.py\", line 277, in __call__\n\n  File \"C:\\Users\\91779\\anaconda3\\lib\\site-packages\\keras\\src\\losses.py\", line 143, in __call__\n\n  File \"C:\\Users\\91779\\anaconda3\\lib\\site-packages\\keras\\src\\losses.py\", line 270, in call\n\n  File \"C:\\Users\\91779\\anaconda3\\lib\\site-packages\\keras\\src\\losses.py\", line 2521, in binary_crossentropy\n\nCast string to float is not supported\n\t [[{{node binary_crossentropy/Cast}}]] [Op:__inference_train_function_1081]"
     ]
    }
   ],
   "source": [
    "import pandas as pd\n",
    "from sklearn.model_selection import train_test_split\n",
    "import tensorflow as tf\n",
    "from tensorflow.keras.models import Sequential\n",
    "from tensorflow.keras.layers import Dense\n",
    "\n",
    "# Assuming you have loaded your dataset into a DataFrame 'df'\n",
    "\n",
    "# Sample data for demonstration purposes\n",
    "data = {\n",
    "    'fixed acidity': [7.4, 7.8, 7.8],\n",
    "    'volatile acidity': [0.7, 0.88, 0.76],\n",
    "    'citric acid': [0, 0, 0.04],\n",
    "    'residual sugar': [1.9, 2.6, 2.3],\n",
    "    'chlorides': [0.076, 0.098, 0.092],\n",
    "    'free sulfur dioxide': [11, 25, 15],\n",
    "    'total sulfur dioxide': [34, 67, 54],\n",
    "    'density': [0.9978, 0.9968, 0.997],\n",
    "    'pH': [3.51, 3.2, 3.26],\n",
    "    'sulphates': [0.56, 0.68, 0.65],\n",
    "    'alcohol': [9.4, 9.8, 9.8],\n",
    "    'quality': ['bad', 'bad', 'bad']\n",
    "}\n",
    "\n",
    "df = pd.DataFrame(data)\n",
    "\n",
    "# Assuming 'df' contains your features and the target variable is named 'quality'\n",
    "X = df.drop('quality', axis=1)\n",
    "y = df['quality']\n",
    "\n",
    "# Split the data into training, validation, and test sets\n",
    "X_train, X_temp, y_train, y_temp = train_test_split(X, y, test_size=0.4, random_state=42)\n",
    "X_val, X_test, y_val, y_test = train_test_split(X_temp, y_temp, test_size=0.5, random_state=42)\n",
    "\n",
    "# Define the model\n",
    "model = Sequential([\n",
    "    Dense(128, activation='relu', input_dim=X_train.shape[1]),  # First hidden layer with 128 neurons\n",
    "    Dense(64, activation='relu'),  # Second hidden layer with 64 neurons\n",
    "    Dense(1, activation='sigmoid')  # Output layer with 1 neuron for binary classification\n",
    "])\n",
    "\n",
    "# Compile the model\n",
    "model.compile(optimizer='adam', loss='binary_crossentropy', metrics=['accuracy'])\n",
    "\n",
    "# Train the model\n",
    "history = model.fit(X_train, y_train, epochs=10, batch_size=32, validation_data=(X_val, y_val))\n",
    "\n",
    "# Evaluate the model on the test set\n",
    "test_loss, test_acc = model.evaluate(X_test, y_test)\n",
    "print('\\nTest accuracy:', test_acc)\n"
   ]
  },
  {
   "cell_type": "code",
   "execution_count": null,
   "id": "168d7642",
   "metadata": {},
   "outputs": [],
   "source": []
  }
 ],
 "metadata": {
  "kernelspec": {
   "display_name": "Python 3 (ipykernel)",
   "language": "python",
   "name": "python3"
  },
  "language_info": {
   "codemirror_mode": {
    "name": "ipython",
    "version": 3
   },
   "file_extension": ".py",
   "mimetype": "text/x-python",
   "name": "python",
   "nbconvert_exporter": "python",
   "pygments_lexer": "ipython3",
   "version": "3.10.9"
  }
 },
 "nbformat": 4,
 "nbformat_minor": 5
}
